<?xml version="1.0" encoding="UTF-8"?>
<!-- Generated by org.testng.reporters.JUnitReportReporter -->
<testsuite skipped="5" hostname="RAMESHRADH" name="org.failedtest.FailedTest" tests="9" failures="1" timestamp="11 Apr 2021 10:04:25 GMT" time="0.025" errors="0">
  <testcase name="testA3" time="0.001" classname="org.failedtest.FailedTest">
    <skipped/>
  </testcase> <!-- testA3 -->
  <testcase name="testA3" time="0.001" classname="org.failedtest.FailedTest">
    <skipped/>
  </testcase> <!-- testA3 -->
  <testcase name="testA4" time="0.001" classname="org.failedtest.FailedTest"/>
  <testcase name="TestA1" time="0.013" classname="org.failedtest.FailedTest"/>
  <testcase name="testA3" time="0.001" classname="org.failedtest.FailedTest">
    <failure type="java.lang.AssertionError" message="expected [true] but found [false]">
      <![CDATA[java.lang.AssertionError: expected [true] but found [false]
	at org.testng.Assert.fail(Assert.java:94)
	at org.testng.Assert.failNotEquals(Assert.java:513)
	at org.testng.Assert.assertTrue(Assert.java:42)
	at org.testng.Assert.assertTrue(Assert.java:52)
	at org.failedtest.FailedTest.testA3(FailedTest.java:20)
	at sun.reflect.NativeMethodAccessorImpl.invoke0(Native Method)
	at sun.reflect.NativeMethodAccessorImpl.invoke(Unknown Source)
	at sun.reflect.DelegatingMethodAccessorImpl.invoke(Unknown Source)
	at java.lang.reflect.Method.invoke(Unknown Source)
	at org.testng.internal.MethodInvocationHelper.invokeMethod(MethodInvocationHelper.java:100)
	at org.testng.internal.Invoker.invokeMethod(Invoker.java:646)
	at org.testng.internal.Invoker.retryFailed(Invoker.java:958)
	at org.testng.internal.Invoker.invokeTestMethods(Invoker.java:1160)
	at org.testng.internal.TestMethodWorker.invokeTestMethods(TestMethodWorker.java:129)
	at org.testng.internal.TestMethodWorker.run(TestMethodWorker.java:112)
	at org.testng.TestRunner.privateRun(TestRunner.java:753)
	at org.testng.TestRunner.run(TestRunner.java:607)
	at org.testng.SuiteRunner.runTest(SuiteRunner.java:368)
	at org.testng.SuiteRunner.runSequentially(SuiteRunner.java:363)
	at org.testng.SuiteRunner.privateRun(SuiteRunner.java:321)
	at org.testng.SuiteRunner.run(SuiteRunner.java:270)
	at org.testng.SuiteRunnerWorker.runSuite(SuiteRunnerWorker.java:52)
	at org.testng.SuiteRunnerWorker.run(SuiteRunnerWorker.java:86)
	at org.testng.TestNG.runSuitesSequentially(TestNG.java:1284)
	at org.testng.TestNG.runSuitesLocally(TestNG.java:1209)
	at org.testng.TestNG.runSuites(TestNG.java:1124)
	at org.testng.TestNG.run(TestNG.java:1096)
	at org.testng.remote.AbstractRemoteTestNG.run(AbstractRemoteTestNG.java:132)
	at org.testng.remote.RemoteTestNG.initAndRun(RemoteTestNG.java:236)
	at org.testng.remote.RemoteTestNG.main(RemoteTestNG.java:81)
]]>
    </failure>
  </testcase> <!-- testA3 -->
  <testcase name="testA3" time="0.003" classname="org.failedtest.FailedTest">
    <skipped/>
  </testcase> <!-- testA3 -->
  <testcase name="TestA2" time="0.002" classname="org.failedtest.FailedTest"/>
  <testcase name="testA3" time="0.002" classname="org.failedtest.FailedTest">
    <skipped/>
  </testcase> <!-- testA3 -->
  <testcase name="testA3" time="0.001" classname="org.failedtest.FailedTest">
    <skipped/>
  </testcase> <!-- testA3 -->
</testsuite> <!-- org.failedtest.FailedTest -->
